Workbook

Sheet Mitarbeiter
A1: Mitarbeiter-ID | B1: Name | C1: Abteilung | D1: Standort
A2: 1001 | B2: Aleksandr Weinhage | C2: IT | D2: Berlin
A3: 1002 | B3: Eleni Hauffer | C3: IT | D3: Berlin
A4: 1003 | B4: Paul Dobes-Stiffel | C4: Produktion | D4: Hamburg
A5: 1004 | B5: Klemens Löffler | C5: Vertrieb | D5: Hamburg
A6: 1005 | B6: Alexandre Davids | C6: Vertrieb | D6: Berlin
A7: 1006 | B7: Eric Patberg B.Sc. | C7: Vertrieb | D7: Hamburg
A8: 1007 | B8: Orhan Siering MBA. | C8: IT | D8: Berlin
A9: 1008 | B9: Dipl.-Ing. Klaus-Werner Holsten B.Sc. | C9: IT | D9: Hamburg
A10: 1009 | B10: Univ.Prof. Heimo Karge | C10: Marketing | D10: Hamburg
A11: 1010 | B11: Carolin Hande | C11: IT | D11: Hamburg
A12: 1011 | B12: Auguste Davids | C12: IT | D12: Hamburg
A13: 1012 | B13: Ariane Klemt-Kaul | C13: IT | D13: München

Sheet Geraete
A1: Gerätenummer | B1: Gerätetyp | C1: Modell | D1: Kaufdatum | E1: Netto-Kaufpreis | F1: Standort
A2: G0001 | B2: Tablet | C2: Galaxy Tab | D2: 44937 | E2: 1342.83 | F2: Berlin
A3: G0002 | B3: Tablet | C3: Surface Go | D3: 44250 | E3: 1076.18 | F3: München
A4: G0003 | B4: Tablet | C4: iPad | D4: 45543 | E4: 1931.54 | F4: München
A5: G0004 | B5: Laptop | C5: Dell XPS | D5: 45782 | E5: 1007.88 | F5: München
A6: G0005 | B6: Drucker | C6: Canon Pixma | D6: 44503 | E6: 823.23 | F6: Berlin
A7: G0006 | B7: Smartphone | C7: Samsung S21 | D7: 45292 | E7: 1257.96 | F7: München
A8: G0007 | B8: Laptop | C8: Lenovo ThinkPad | D8: 44360 | E8: 869.09 | F8: Hamburg
A9: G0008 | B9: Beamer | C9: Epson EB | D9: 45831 | E9: 1323.76 | F9: Hamburg
A10: G0009 | B10: Laptop | C10: Dell XPS | D10: 45026 | E10: 1458.02 | F10: München
A11: G0010 | B11: Laptop | C11: Dell XPS | D11: 45239 | E11: 1786.37 | F11: München
A12: G0011 | B12: Drucker | C12: Brother HL | D12: 45909 | E12: 1417.1 | F12: München
A13: G0012 | B13: Tablet | C13: Galaxy Tab | D13: 44713 | E13: 968.43 | F13: Hamburg
... A36: G0035 | B36: Beamer | C36: BenQ MW550 | D36: 45294 | E36: 644.54 | F36: Berlin

Sheet Ausleihen
A1: Gerätenummer | B1: Mitarbeiter-ID | C1: Ausgabe am | D1: Rückgabe am
A2: G0035 | B2: 1009 | C2: 45421
A3: G0021 | B3: 1008 | C3: 45930 | D3: 45935
A4: G0024 | B4: 1005 | C4: 45743 | D4: 45868
A5: G0016 | B5: 1010 | C5: 45866
A6: G0006 | B6: 1012 | C6: 45808 | D6: 45818
A7: G0005 | B7: 1009 | C7: 45389
A8: G0009 | B8: 1011 | C8: 45850 | D8: 45853
A9: G0011 | B9: 1005 | C9: 45837 | D9: 45898
A10: G0028 | B10: 1004 | C10: 45523
A11: G0013 | B11: 1012 | C11: 45419 | D11: 45470
A12: G0024 | B12: 1008 | C12: 45375
A13: G0029 | B13: 1002 | C13: 45921 | D13: 45934
A14: G0005 | B14: 1006 | C14: 45892 | D14: 45922
A15: G0015 | B15: 1010 | C15: 45377 | D15: 45886
A16: G0005 | B16: 1012 | C16: 45599
A17: G0015 | B17: 1002 | C17: 45519
A18: G0022 | B18: 1002 | C18: 45899 | D18: 45930
A19: G0018 | B19: 1011 | C19: 45568 | D19: 45623
A20: G0035 | B20: 1003 | C20: 45417
A21: G0031 | B21: 1004 | C21: 45320
A22: G0027 | B22: 1004 | C22: 45403 | D22: 45839
A23: G0028 | B23: 1006 | C23: 45630 | D23: 45732
A24: G0030 | B24: 1012 | C24: 45792 | D24: 45905
A25: G0007 | B25: 1001 | C25: 45544 | D25: 45854
A26: G0022 | B26: 1002 | C26: 45493 | D26: 45663
A27: G0013 | B27: 1009 | C27: 45319 | D27: 45714
A28: G0028 | B28: 1003 | C28: 45595 | D28: 45630
A29: G0016 | B29: 1002 | C29: 45799 | D29: 45808
A30: G0007 | B30: 1001 | C30: 45880
A31: G0035 | B31: 1001 | C31: 45297
A32: G0016 | B32: 1003 | C32: 45330 | D32: 45817
A33: G0031 | B33: 1004 | C33: 45336
A34: G0004 | B34: 1003 | C34: 45827 | D34: 45908
A35: G0025 | B35: 1005 | C35: 45675
A36: G0030 | B36: 1005 | C36: 45261 | D36: 45559
A37: G0032 | B37: 1003 | C37: 45508 | D37: 45871
A38: G0014 | B38: 1001 | C38: 45622 | D38: 45719
A39: G0035 | B39: 1001 | C39: 45641
A40: G0004 | B40: 1001 | C40: 45880 | D40: 45881
...

Sheet Geraete_Ausleihen
A1: Gerätenummer | B1: Mitarbeiter-ID | C1: Ausgabe am | D1: Rückgabe am | E1: Gerätetyp | F1: Modell | G1: Kaufdatum | H1: Netto-Kaufpreis | I1: Standort
A2: =Ausleihen!A2 -> G0035 | B2: =Ausleihen!B2 -> 1009 | C2: =Ausleihen!C2 -> 45421 | D2: =IF(Ausleihen!D2="","",Ausleihen!D2) | E2: =INDEX(Geraete!$B$2:$B$36,MATCH($A2,Geraete!$A$2:$A$36,0)) -> Beamer | F2: =INDEX(Geraete!$C$2:$C$36,MATCH($A2,Geraete!$A$2:$A$36,0)) -> BenQ MW550 | G2: =INDEX(Geraete!$D$2:$D$36,MATCH($A2,Geraete!$A$2:$A$36,0)) -> 45294 | H2: =INDEX(Geraete!$E$2:$E$36,MATCH($A2,Geraete!$A$2:$A$36,0)) -> 644.54 | I2: =INDEX(Geraete!$F$2:$F$36,MATCH($A2,Geraete!$A$2:$A$36,0)) -> Berlin
A3: =Ausleihen!A3 -> G0021 | B3: =Ausleihen!B3 -> 1008 | C3: =Ausleihen!C3 -> 45930 | D3: =IF(Ausleihen!D3="","",Ausleihen!D3) -> 45935 | E3: =INDEX(Geraete!$B$2:$B$36,MATCH($A3,Geraete!$A$2:$A$36,0)) -> Monitor | F3: =INDEX(Geraete!$C$2:$C$36,MATCH($A3,Geraete!$A$2:$A$36,0)) -> Samsung Curved | G3: =INDEX(Geraete!$D$2:$D$36,MATCH($A3,Geraete!$A$2:$A$36,0)) -> 44979 | H3: =INDEX(Geraete!$E$2:$E$36,MATCH($A3,Geraete!$A$2:$A$36,0)) -> 1134.16 | I3: =INDEX(Geraete!$F$2:$F$36,MATCH($A3,Geraete!$A$2:$A$36,0)) -> München
A4: =Ausleihen!A4 -> G0024 | B4: =Ausleihen!B4 -> 1005 | C4: =Ausleihen!C4 -> 45743 | D4: =IF(Ausleihen!D4="","",Ausleihen!D4) -> 45868 | E4: =INDEX(Geraete!$B$2:$B$36,MATCH($A4,Geraete!$A$2:$A$36,0)) -> Monitor | F4: =INDEX(Geraete!$C$2:$C$36,MATCH($A4,Geraete!$A$2:$A$36,0)) -> Dell UltraSharp | G4: =INDEX(Geraete!$D$2:$D$36,MATCH($A4,Geraete!$A$2:$A$36,0)) -> 44621 | H4: =INDEX(Geraete!$E$2:$E$36,MATCH($A4,Geraete!$A$2:$A$36,0)) -> 750.91 | I4: =INDEX(Geraete!$F$2:$F$36,MATCH($A4,Geraete!$A$2:$A$36,0)) -> Berlin
A5: =Ausleihen!A5 -> G0016 | B5: =Ausleihen!B5 -> 1010 | C5: =Ausleihen!C5 -> 45866 | D5: =IF(Ausleihen!D5="","",Ausleihen!D5) | E5: =INDEX(Geraete!$B$2:$B$36,MATCH($A5,Geraete!$A$2:$A$36,0)) -> Drucker | F5: =INDEX(Geraete!$C$2:$C$36,MATCH($A5,Geraete!$A$2:$A$36,0)) -> Canon Pixma | G5: =INDEX(Geraete!$D$2:$D$36,MATCH($A5,Geraete!$A$2:$A$36,0)) -> 45015 | H5: =INDEX(Geraete!$E$2:$E$36,MATCH($A5,Geraete!$A$2:$A$36,0)) -> 1501.06 | I5: =INDEX(Geraete!$F$2:$F$36,MATCH($A5,Geraete!$A$2:$A$36,0)) -> Berlin
A6: =Ausleihen!A6 -> G0006 | B6: =Ausleihen!B6 -> 1012 | C6: =Ausleihen!C6 -> 45808 | D6: =IF(Ausleihen!D6="","",Ausleihen!D6) -> 45818 | E6: =INDEX(Geraete!$B$2:$B$36,MATCH($A6,Geraete!$A$2:$A$36,0)) -> Smartphone | F6: =INDEX(Geraete!$C$2:$C$36,MATCH($A6,Geraete!$A$2:$A$36,0)) -> Samsung S21 | G6: =INDEX(Geraete!$D$2:$D$36,MATCH($A6,Geraete!$A$2:$A$36,0)) -> 45292 | H6: =INDEX(Geraete!$E$2:$E$36,MATCH($A6,Geraete!$A$2:$A$36,0)) -> 1257.96 | I6: =INDEX(Geraete!$F$2:$F$36,MATCH($A6,Geraete!$A$2:$A$36,0)) -> München
A7: =Ausleihen!A7 -> G0005 | B7: =Ausleihen!B7 -> 1009 | C7: =Ausleihen!C7 -> 45389 | D7: =IF(Ausleihen!D7="","",Ausleihen!D7) | E7: =INDEX(Geraete!$B$2:$B$36,MATCH($A7,Geraete!$A$2:$A$36,0)) -> Drucker | F7: =INDEX(Geraete!$C$2:$C$36,MATCH($A7,Geraete!$A$2:$A$36,0)) -> Canon Pixma | G7: =INDEX(Geraete!$D$2:$D$36,MATCH($A7,Geraete!$A$2:$A$36,0)) -> 44503 | H7: =INDEX(Geraete!$E$2:$E$36,MATCH($A7,Geraete!$A$2:$A$36,0)) -> 823.23 | I7: =INDEX(Geraete!$F$2:$F$36,MATCH($A7,Geraete!$A$2:$A$36,0)) -> Berlin
A8: =Ausleihen!A8 -> G0009 | B8: =Ausleihen!B8 -> 1011 | C8: =Ausleihen!C8 -> 45850 | D8: =IF(Ausleihen!D8="","",Ausleihen!D8) -> 45853 | E8: =INDEX(Geraete!$B$2:$B$36,MATCH($A8,Geraete!$A$2:$A$36,0)) -> Laptop | F8: =INDEX(Geraete!$C$2:$C$36,MATCH($A8,Geraete!$A$2:$A$36,0)) -> Dell XPS | G8: =INDEX(Geraete!$D$2:$D$36,MATCH($A8,Geraete!$A$2:$A$36,0)) -> 45026 | H8: =INDEX(Geraete!$E$2:$E$36,MATCH($A8,Geraete!$A$2:$A$36,0)) -> 1458.02 | I8: =INDEX(Geraete!$F$2:$F$36,MATCH($A8,Geraete!$A$2:$A$36,0)) -> München
A9: =Ausleihen!A9 -> G0011 | B9: =Ausleihen!B9 -> 1005 | C9: =Ausleihen!C9 -> 45837 | D9: =IF(Ausleihen!D9="","",Ausleihen!D9) -> 45898 | E9: =INDEX(Geraete!$B$2:$B$36,MATCH($A9,Geraete!$A$2:$A$36,0)) -> Drucker | F9: =INDEX(Geraete!$C$2:$C$36,MATCH($A9,Geraete!$A$2:$A$36,0)) -> Brother HL | G9: =INDEX(Geraete!$D$2:$D$36,MATCH($A9,Geraete!$A$2:$A$36,0)) -> 45909 | H9: =INDEX(Geraete!$E$2:$E$36,MATCH($A9,Geraete!$A$2:$A$36,0)) -> 1417.1 | I9: =INDEX(Geraete!$F$2:$F$36,MATCH($A9,Geraete!$A$2:$A$36,0)) -> München
A10: =Ausleihen!A10 -> G0028 | B10: =Ausleihen!B10 -> 1004 | C10: =Ausleihen!C10 -> 45523 | D10: =IF(Ausleihen!D10="","",Ausleihen!D10) | E10: =INDEX(Geraete!$B$2:$B$36,MATCH($A10,Geraete!$A$2:$A$36,0)) -> Beamer | F10: =INDEX(Geraete!$C$2:$C$36,MATCH($A10,Geraete!$A$2:$A$36,0)) -> Epson EB | G10: =INDEX(Geraete!$D$2:$D$36,MATCH($A10,Geraete!$A$2:$A$36,0)) -> 44945 | H10: =INDEX(Geraete!$E$2:$E$36,MATCH($A10,Geraete!$A$2:$A$36,0)) -> 1246.58 | I10: =INDEX(Geraete!$F$2:$F$36,MATCH($A10,Geraete!$A$2:$A$36,0)) -> Hamburg
A11: =Ausleihen!A11 -> G0013 | B11: =Ausleihen!B11 -> 1012 | C11: =Ausleihen!C11 -> 45419 | D11: =IF(Ausleihen!D11="","",Ausleihen!D11) -> 45470 | E11: =INDEX(Geraete!$B$2:$B$36,MATCH($A11,Geraete!$A$2:$A$36,0)) -> Drucker | F11: =INDEX(Geraete!$C$2:$C$36,MATCH($A11,Geraete!$A$2:$A$36,0)) -> Canon Pixma | G11: =INDEX(Geraete!$D$2:$D$36,MATCH($A11,Geraete!$A$2:$A$36,0)) -> 44332 | H11: =INDEX(Geraete!$E$2:$E$36,MATCH($A11,Geraete!$A$2:$A$36,0)) -> 1898.65 | I11: =INDEX(Geraete!$F$2:$F$36,MATCH($A11,Geraete!$A$2:$A$36,0)) -> Hamburg
A12: =Ausleihen!A12 -> G0024 | B12: =Ausleihen!B12 -> 1008 | C12: =Ausleihen!C12 -> 45375 | D12: =IF(Ausleihen!D12="","",Ausleihen!D12) | E12: =INDEX(Geraete!$B$2:$B$36,MATCH($A12,Geraete!$A$2:$A$36,0)) -> Monitor | F12: =INDEX(Geraete!$C$2:$C$36,MATCH($A12,Geraete!$A$2:$A$36,0)) -> Dell UltraSharp | G12: =INDEX(Geraete!$D$2:$D$36,MATCH($A12,Geraete!$A$2:$A$36,0)) -> 44621 | H12: =INDEX(Geraete!$E$2:$E$36,MATCH($A12,Geraete!$A$2:$A$36,0)) -> 750.91 | I12: =INDEX(Geraete!$F$2:$F$36,MATCH($A12,Geraete!$A$2:$A$36,0)) -> Berlin
A13: =Ausleihen!A13 -> G0029 | B13: =Ausleihen!B13 -> 1002 | C13: =Ausleihen!C13 -> 45921 | D13: =IF(Ausleihen!D13="","",Ausleihen!D13) -> 45934 | E13: =INDEX(Geraete!$B$2:$B$36,MATCH($A13,Geraete!$A$2:$A$36,0)) -> Laptop | F13: =INDEX(Geraete!$C$2:$C$36,MATCH($A13,Geraete!$A$2:$A$36,0)) -> Lenovo ThinkPad | G13: =INDEX(Geraete!$D$2:$D$36,MATCH($A13,Geraete!$A$2:$A$36,0)) -> 44337 | H13: =INDEX(Geraete!$E$2:$E$36,MATCH($A13,Geraete!$A$2:$A$36,0)) -> 1553.15 | I13: =INDEX(Geraete!$F$2:$F$36,MATCH($A13,Geraete!$A$2:$A$36,0)) -> Hamburg
... A46: =Ausleihen!A46 -> G0006 | B46: =Ausleihen!B46 -> 1007 | C46: =Ausleihen!C46 -> 45476 | D46: =IF(Ausleihen!D46="","",Ausleihen!D46) | E46: =INDEX(Geraete!$B$2:$B$36,MATCH($A46,Geraete!$A$2:$A$36,0)) -> Smartphone | F46: =INDEX(Geraete!$C$2:$C$36,MATCH($A46,Geraete!$A$2:$A$36,0)) -> Samsung S21 | G46: =INDEX(Geraete!$D$2:$D$36,MATCH($A46,Geraete!$A$2:$A$36,0)) -> 45292 | H46: =INDEX(Geraete!$E$2:$E$36,MATCH($A46,Geraete!$A$2:$A$36,0)) -> 1257.96 | I46: =INDEX(Geraete!$F$2:$F$36,MATCH($A46,Geraete!$A$2:$A$36,0)) -> München

Sheet Gesamt
A1: Gerätenummer | B1: Mitarbeiter-ID | C1: Ausgabe am | D1: Rückgabe am | E1: Gerätetyp | F1: Modell | G1: Kaufdatum | H1: Netto-Kaufpreis | I1: Standort Gerät | J1: Name | K1: Abteilung | L1: Standort Mitarbeiter
A2: =Ausleihen!A2 -> G0035 | B2: =Ausleihen!B2 -> 1009 | C2: =Ausleihen!C2 -> 45421 | D2: =IF(Ausleihen!D2="","",Ausleihen!D2) | E2: =INDEX(Geraete!$B$2:$B$36,MATCH($A2,Geraete!$A$2:$A$36,0)) -> Beamer | F2: =INDEX(Geraete!$C$2:$C$36,MATCH($A2,Geraete!$A$2:$A$36,0)) -> BenQ MW550 | G2: =INDEX(Geraete!$D$2:$D$36,MATCH($A2,Geraete!$A$2:$A$36,0)) -> 45294 | H2: =INDEX(Geraete!$E$2:$E$36,MATCH($A2,Geraete!$A$2:$A$36,0)) -> 644.54 | I2: =INDEX(Geraete!$F$2:$F$36,MATCH($A2,Geraete!$A$2:$A$36,0)) -> Berlin | J2: =INDEX(Mitarbeiter!$B$2:$B$13,MATCH($B2,Mitarbeiter!$A$2:$A$13,0)) -> Univ.Prof. Heimo Karge | K2: =INDEX(Mitarbeiter!$C$2:$C$13,MATCH($B2,Mitarbeiter!$A$2:$A$13,0)) -> Marketing | L2: =INDEX(Mitarbeiter!$D$2:$D$13,MATCH($B2,Mitarbeiter!$A$2:$A$13,0)) -> Hamburg
A3: =Ausleihen!A3 -> G0021 | B3: =Ausleihen!B3 -> 1008 | C3: =Ausleihen!C3 -> 45930 | D3: =IF(Ausleihen!D3="","",Ausleihen!D3) -> 45935 | E3: =INDEX(Geraete!$B$2:$B$36,MATCH($A3,Geraete!$A$2:$A$36,0)) -> Monitor | F3: =INDEX(Geraete!$C$2:$C$36,MATCH($A3,Geraete!$A$2:$A$36,0)) -> Samsung Curved | G3: =INDEX(Geraete!$D$2:$D$36,MATCH($A3,Geraete!$A$2:$A$36,0)) -> 44979 | H3: =INDEX(Geraete!$E$2:$E$36,MATCH($A3,Geraete!$A$2:$A$36,0)) -> 1134.16 | I3: =INDEX(Geraete!$F$2:$F$36,MATCH($A3,Geraete!$A$2:$A$36,0)) -> München | J3: =INDEX(Mitarbeiter!$B$2:$B$13,MATCH($B3,Mitarbeiter!$A$2:$A$13,0)) -> Dipl.-Ing. Klaus-Werner Holsten B.Sc. | K3: =INDEX(Mitarbeiter!$C$2:$C$13,MATCH($B3,Mitarbeiter!$A$2:$A$13,0)) -> IT | L3: =INDEX(Mitarbeiter!$D$2:$D$13,MATCH($B3,Mitarbeiter!$A$2:$A$13,0)) -> Hamburg
A4: =Ausleihen!A4 -> G0024 | B4: =Ausleihen!B4 -> 1005 | C4: =Ausleihen!C4 -> 45743 | D4: =IF(Ausleihen!D4="","",Ausleihen!D4) -> 45868 | E4: =INDEX(Geraete!$B$2:$B$36,MATCH($A4,Geraete!$A$2:$A$36,0)) -> Monitor | F4: =INDEX(Geraete!$C$2:$C$36,MATCH($A4,Geraete!$A$2:$A$36,0)) -> Dell UltraSharp | G4: =INDEX(Geraete!$D$2:$D$36,MATCH($A4,Geraete!$A$2:$A$36,0)) -> 44621 | H4: =INDEX(Geraete!$E$2:$E$36,MATCH($A4,Geraete!$A$2:$A$36,0)) -> 750.91 | I4: =INDEX(Geraete!$F$2:$F$36,MATCH($A4,Geraete!$A$2:$A$36,0)) -> Berlin | J4: =INDEX(Mitarbeiter!$B$2:$B$13,MATCH($B4,Mitarbeiter!$A$2:$A$13,0)) -> Alexandre Davids | K4: =INDEX(Mitarbeiter!$C$2:$C$13,MATCH($B4,Mitarbeiter!$A$2:$A$13,0)) -> Vertrieb | L4: =INDEX(Mitarbeiter!$D$2:$D$13,MATCH($B4,Mitarbeiter!$A$2:$A$13,0)) -> Berlin
A5: =Ausleihen!A5 -> G0016 | B5: =Ausleihen!B5 -> 1010 | C5: =Ausleihen!C5 -> 45866 | D5: =IF(Ausleihen!D5="","",Ausleihen!D5) | E5: =INDEX(Geraete!$B$2:$B$36,MATCH($A5,Geraete!$A$2:$A$36,0)) -> Drucker | F5: =INDEX(Geraete!$C$2:$C$36,MATCH($A5,Geraete!$A$2:$A$36,0)) -> Canon Pixma | G5: =INDEX(Geraete!$D$2:$D$36,MATCH($A5,Geraete!$A$2:$A$36,0)) -> 45015 | H5: =INDEX(Geraete!$E$2:$E$36,MATCH($A5,Geraete!$A$2:$A$36,0)) -> 1501.06 | I5: =INDEX(Geraete!$F$2:$F$36,MATCH($A5,Geraete!$A$2:$A$36,0)) -> Berlin | J5: =INDEX(Mitarbeiter!$B$2:$B$13,MATCH($B5,Mitarbeiter!$A$2:$A$13,0)) -> Carolin Hande | K5: =INDEX(Mitarbeiter!$C$2:$C$13,MATCH($B5,Mitarbeiter!$A$2:$A$13,0)) -> IT | L5: =INDEX(Mitarbeiter!$D$2:$D$13,MATCH($B5,Mitarbeiter!$A$2:$A$13,0)) -> Hamburg
A6: =Ausleihen!A6 -> G0006 | B6: =Ausleihen!B6 -> 1012 | C6: =Ausleihen!C6 -> 45808 | D6: =IF(Ausleihen!D6="","",Ausleihen!D6) -> 45818 | E6: =INDEX(Geraete!$B$2:$B$36,MATCH($A6,Geraete!$A$2:$A$36,0)) -> Smartphone | F6: =INDEX(Geraete!$C$2:$C$36,MATCH($A6,Geraete!$A$2:$A$36,0)) -> Samsung S21 | G6: =INDEX(Geraete!$D$2:$D$36,MATCH($A6,Geraete!$A$2:$A$36,0)) -> 45292 | H6: =INDEX(Geraete!$E$2:$E$36,MATCH($A6,Geraete!$A$2:$A$36,0)) -> 1257.96 | I6: =INDEX(Geraete!$F$2:$F$36,MATCH($A6,Geraete!$A$2:$A$36,0)) -> München | J6: =INDEX(Mitarbeiter!$B$2:$B$13,MATCH($B6,Mitarbeiter!$A$2:$A$13,0)) -> Ariane Klemt-Kaul | K6: =INDEX(Mitarbeiter!$C$2:$C$13,MATCH($B6,Mitarbeiter!$A$2:$A$13,0)) -> IT | L6: =INDEX(Mitarbeiter!$D$2:$D$13,MATCH($B6,Mitarbeiter!$A$2:$A$13,0)) -> München
A7: =Ausleihen!A7 -> G0005 | B7: =Ausleihen!B7 -> 1009 | C7: =Ausleihen!C7 -> 45389 | D7: =IF(Ausleihen!D7="","",Ausleihen!D7) | E7: =INDEX(Geraete!$B$2:$B$36,MATCH($A7,Geraete!$A$2:$A$36,0)) -> Drucker | F7: =INDEX(Geraete!$C$2:$C$36,MATCH($A7,Geraete!$A$2:$A$36,0)) -> Canon Pixma | G7: =INDEX(Geraete!$D$2:$D$36,MATCH($A7,Geraete!$A$2:$A$36,0)) -> 44503 | H7: =INDEX(Geraete!$E$2:$E$36,MATCH($A7,Geraete!$A$2:$A$36,0)) -> 823.23 | I7: =INDEX(Geraete!$F$2:$F$36,MATCH($A7,Geraete!$A$2:$A$36,0)) -> Berlin | J7: =INDEX(Mitarbeiter!$B$2:$B$13,MATCH($B7,Mitarbeiter!$A$2:$A$13,0)) -> Univ.Prof. Heimo Karge | K7: =INDEX(Mitarbeiter!$C$2:$C$13,MATCH($B7,Mitarbeiter!$A$2:$A$13,0)) -> Marketing | L7: =INDEX(Mitarbeiter!$D$2:$D$13,MATCH($B7,Mitarbeiter!$A$2:$A$13,0)) -> Hamburg
A8: =Ausleihen!A8 -> G0009 | B8: =Ausleihen!B8 -> 1011 | C8: =Ausleihen!C8 -> 45850 | D8: =IF(Ausleihen!D8="","",Ausleihen!D8) -> 45853 | E8: =INDEX(Geraete!$B$2:$B$36,MATCH($A8,Geraete!$A$2:$A$36,0)) -> Laptop | F8: =INDEX(Geraete!$C$2:$C$36,MATCH($A8,Geraete!$A$2:$A$36,0)) -> Dell XPS | G8: =INDEX(Geraete!$D$2:$D$36,MATCH($A8,Geraete!$A$2:$A$36,0)) -> 45026 | H8: =INDEX(Geraete!$E$2:$E$36,MATCH($A8,Geraete!$A$2:$A$36,0)) -> 1458.02 | I8: =INDEX(Geraete!$F$2:$F$36,MATCH($A8,Geraete!$A$2:$A$36,0)) -> München | J8: =INDEX(Mitarbeiter!$B$2:$B$13,MATCH($B8,Mitarbeiter!$A$2:$A$13,0)) -> Auguste Davids | K8: =INDEX(Mitarbeiter!$C$2:$C$13,MATCH($B8,Mitarbeiter!$A$2:$A$13,0)) -> IT | L8: =INDEX(Mitarbeiter!$D$2:$D$13,MATCH($B8,Mitarbeiter!$A$2:$A$13,0)) -> Hamburg
A9: =Ausleihen!A9 -> G0011 | B9: =Ausleihen!B9 -> 1005 | C9: =Ausleihen!C9 -> 45837 | D9: =IF(Ausleihen!D9="","",Ausleihen!D9) -> 45898 | E9: =INDEX(Geraete!$B$2:$B$36,MATCH($A9,Geraete!$A$2:$A$36,0)) -> Drucker | F9: =INDEX(Geraete!$C$2:$C$36,MATCH($A9,Geraete!$A$2:$A$36,0)) -> Brother HL | G9: =INDEX(Geraete!$D$2:$D$36,MATCH($A9,Geraete!$A$2:$A$36,0)) -> 45909 | H9: =INDEX(Geraete!$E$2:$E$36,MATCH($A9,Geraete!$A$2:$A$36,0)) -> 1417.1 | I9: =INDEX(Geraete!$F$2:$F$36,MATCH($A9,Geraete!$A$2:$A$36,0)) -> München | J9: =INDEX(Mitarbeiter!$B$2:$B$13,MATCH($B9,Mitarbeiter!$A$2:$A$13,0)) -> Alexandre Davids | K9: =INDEX(Mitarbeiter!$C$2:$C$13,MATCH($B9,Mitarbeiter!$A$2:$A$13,0)) -> Vertrieb | L9: =INDEX(Mitarbeiter!$D$2:$D$13,MATCH($B9,Mitarbeiter!$A$2:$A$13,0)) -> Berlin
A10: =Ausleihen!A10 -> G0028 | B10: =Ausleihen!B10 -> 1004 | C10: =Ausleihen!C10 -> 45523 | D10: =IF(Ausleihen!D10="","",Ausleihen!D10) | E10: =INDEX(Geraete!$B$2:$B$36,MATCH($A10,Geraete!$A$2:$A$36,0)) -> Beamer | F10: =INDEX(Geraete!$C$2:$C$36,MATCH($A10,Geraete!$A$2:$A$36,0)) -> Epson EB | G10: =INDEX(Geraete!$D$2:$D$36,MATCH($A10,Geraete!$A$2:$A$36,0)) -> 44945 | H10: =INDEX(Geraete!$E$2:$E$36,MATCH($A10,Geraete!$A$2:$A$36,0)) -> 1246.58 | I10: =INDEX(Geraete!$F$2:$F$36,MATCH($A10,Geraete!$A$2:$A$36,0)) -> Hamburg | J10: =INDEX(Mitarbeiter!$B$2:$B$13,MATCH($B10,Mitarbeiter!$A$2:$A$13,0)) -> Klemens Löffler | K10: =INDEX(Mitarbeiter!$C$2:$C$13,MATCH($B10,Mitarbeiter!$A$2:$A$13,0)) -> Vertrieb | L10: =INDEX(Mitarbeiter!$D$2:$D$13,MATCH($B10,Mitarbeiter!$A$2:$A$13,0)) -> Hamburg
A11: =Ausleihen!A11 -> G0013 | B11: =Ausleihen!B11 -> 1012 | C11: =Ausleihen!C11 -> 45419 | D11: =IF(Ausleihen!D11="","",Ausleihen!D11) -> 45470 | E11: =INDEX(Geraete!$B$2:$B$36,MATCH($A11,Geraete!$A$2:$A$36,0)) -> Drucker | F11: =INDEX(Geraete!$C$2:$C$36,MATCH($A11,Geraete!$A$2:$A$36,0)) -> Canon Pixma | G11: =INDEX(Geraete!$D$2:$D$36,MATCH($A11,Geraete!$A$2:$A$36,0)) -> 44332 | H11: =INDEX(Geraete!$E$2:$E$36,MATCH($A11,Geraete!$A$2:$A$36,0)) -> 1898.65 | I11: =INDEX(Geraete!$F$2:$F$36,MATCH($A11,Geraete!$A$2:$A$36,0)) -> Hamburg | J11: =INDEX(Mitarbeiter!$B$2:$B$13,MATCH($B11,Mitarbeiter!$A$2:$A$13,0)) -> Ariane Klemt-Kaul | K11: =INDEX(Mitarbeiter!$C$2:$C$13,MATCH($B11,Mitarbeiter!$A$2:$A$13,0)) -> IT | L11: =INDEX(Mitarbeiter!$D$2:$D$13,MATCH($B11,Mitarbeiter!$A$2:$A$13,0)) -> München
A12: =Ausleihen!A12 -> G0024 | B12: =Ausleihen!B12 -> 1008 | C12: =Ausleihen!C12 -> 45375 | D12: =IF(Ausleihen!D12="","",Ausleihen!D12) | E12: =INDEX(Geraete!$B$2:$B$36,MATCH($A12,Geraete!$A$2:$A$36,0)) -> Monitor | F12: =INDEX(Geraete!$C$2:$C$36,MATCH($A12,Geraete!$A$2:$A$36,0)) -> Dell UltraSharp | G12: =INDEX(Geraete!$D$2:$D$36,MATCH($A12,Geraete!$A$2:$A$36,0)) -> 44621 | H12: =INDEX(Geraete!$E$2:$E$36,MATCH($A12,Geraete!$A$2:$A$36,0)) -> 750.91 | I12: =INDEX(Geraete!$F$2:$F$36,MATCH($A12,Geraete!$A$2:$A$36,0)) -> Berlin | J12: =INDEX(Mitarbeiter!$B$2:$B$13,MATCH($B12,Mitarbeiter!$A$2:$A$13,0)) -> Dipl.-Ing. Klaus-Werner Holsten B.Sc. | K12: =INDEX(Mitarbeiter!$C$2:$C$13,MATCH($B12,Mitarbeiter!$A$2:$A$13,0)) -> IT | L12: =INDEX(Mitarbeiter!$D$2:$D$13,MATCH($B12,Mitarbeiter!$A$2:$A$13,0)) -> Hamburg
A13: =Ausleihen!A13 -> G0029 | B13: =Ausleihen!B13 -> 1002 | C13: =Ausleihen!C13 -> 45921 | D13: =IF(Ausleihen!D13="","",Ausleihen!D13) -> 45934 | E13: =INDEX(Geraete!$B$2:$B$36,MATCH($A13,Geraete!$A$2:$A$36,0)) -> Laptop | F13: =INDEX(Geraete!$C$2:$C$36,MATCH($A13,Geraete!$A$2:$A$36,0)) -> Lenovo ThinkPad | G13: =INDEX(Geraete!$D$2:$D$36,MATCH($A13,Geraete!$A$2:$A$36,0)) -> 44337 | H13: =INDEX(Geraete!$E$2:$E$36,MATCH($A13,Geraete!$A$2:$A$36,0)) -> 1553.15 | I13: =INDEX(Geraete!$F$2:$F$36,MATCH($A13,Geraete!$A$2:$A$36,0)) -> Hamburg | J13: =INDEX(Mitarbeiter!$B$2:$B$13,MATCH($B13,Mitarbeiter!$A$2:$A$13,0)) -> Eleni Hauffer | K13: =INDEX(Mitarbeiter!$C$2:$C$13,MATCH($B13,Mitarbeiter!$A$2:$A$13,0)) -> IT | L13: =INDEX(Mitarbeiter!$D$2:$D$13,MATCH($B13,Mitarbeiter!$A$2:$A$13,0)) -> Berlin
... A46: =Ausleihen!A46 -> G0006 | B46: =Ausleihen!B46 -> 1007 | C46: =Ausleihen!C46 -> 45476 | D46: =IF(Ausleihen!D46="","",Ausleihen!D46) | E46: =INDEX(Geraete!$B$2:$B$36,MATCH($A46,Geraete!$A$2:$A$36,0)) -> Smartphone | F46: =INDEX(Geraete!$C$2:$C$36,MATCH($A46,Geraete!$A$2:$A$36,0)) -> Samsung S21 | G46: =INDEX(Geraete!$D$2:$D$36,MATCH($A46,Geraete!$A$2:$A$36,0)) -> 45292 | H46: =INDEX(Geraete!$E$2:$E$36,MATCH($A46,Geraete!$A$2:$A$36,0)) -> 1257.96 | I46: =INDEX(Geraete!$F$2:$F$36,MATCH($A46,Geraete!$A$2:$A$36,0)) -> München | J46: =INDEX(Mitarbeiter!$B$2:$B$13,MATCH($B46,Mitarbeiter!$A$2:$A$13,0)) -> Orhan Siering MBA. | K46: =INDEX(Mitarbeiter!$C$2:$C$13,MATCH($B46,Mitarbeiter!$A$2:$A$13,0)) -> IT | L46: =INDEX(Mitarbeiter!$D$2:$D$13,MATCH($B46,Mitarbeiter!$A$2:$A$13,0)) -> Berlin

Sheet D1_Einsatz
A1: Gerätenummer | B1: Gerätetyp | C1: Modell | D1: Netto-Kaufpreis | E1: Offene Ausleihen | F1: Status | H1: Auswertung
A2: =Geraete!A2 -> G0001 | B2: =Geraete!B2 -> Tablet | C2: =Geraete!C2 -> Galaxy Tab | D2: =Geraete!E2 -> 1342.83 | E2: =COUNTIFS(Ausleihen!$A$2:$A$46,A2,Ausleihen!$D$2:$D$46,"") -> 0 | F2: =IF(E2>0,"im Einsatz","nicht im Einsatz") -> nicht im Einsatz | H2: Geräte nicht im Einsatz | I2: =COUNTIF(F2:F36,"nicht im Einsatz") -> 24
A3: =Geraete!A3 -> G0002 | B3: =Geraete!B3 -> Tablet | C3: =Geraete!C3 -> Surface Go | D3: =Geraete!E3 -> 1076.18 | E3: =COUNTIFS(Ausleihen!$A$2:$A$46,A3,Ausleihen!$D$2:$D$46,"") -> 0 | F3: =IF(E3>0,"im Einsatz","nicht im Einsatz") -> nicht im Einsatz | H3: Gesamtwert nicht im Einsatz | I3: =SUMIF(F2:F36,"nicht im Einsatz",D2:D36) -> 33239.1
A4: =Geraete!A4 -> G0003 | B4: =Geraete!B4 -> Tablet | C4: =Geraete!C4 -> iPad | D4: =Geraete!E4 -> 1931.54 | E4: =COUNTIFS(Ausleihen!$A$2:$A$46,A4,Ausleihen!$D$2:$D$46,"") -> 0 | F4: =IF(E4>0,"im Einsatz","nicht im Einsatz") -> nicht im Einsatz | H4: Geräte im Einsatz | I4: =COUNTIF(F2:F36,"im Einsatz") -> 11
A5: =Geraete!A5 -> G0004 | B5: =Geraete!B5 -> Laptop | C5: =Geraete!C5 -> Dell XPS | D5: =Geraete!E5 -> 1007.88 | E5: =COUNTIFS(Ausleihen!$A$2:$A$46,A5,Ausleihen!$D$2:$D$46,"") -> 0 | F5: =IF(E5>0,"im Einsatz","nicht im Einsatz") -> nicht im Einsatz | H5: Gesamtwert im Einsatz | I5: =SUMIF(F2:F36,"im Einsatz",D2:D36) -> 10608.18
A6: =Geraete!A6 -> G0005 | B6: =Geraete!B6 -> Drucker | C6: =Geraete!C6 -> Canon Pixma | D6: =Geraete!E6 -> 823.23 | E6: =COUNTIFS(Ausleihen!$A$2:$A$46,A6,Ausleihen!$D$2:$D$46,"") -> 2 | F6: =IF(E6>0,"im Einsatz","nicht im Einsatz") -> im Einsatz
A7: =Geraete!A7 -> G0006 | B7: =Geraete!B7 -> Smartphone | C7: =Geraete!C7 -> Samsung S21 | D7: =Geraete!E7 -> 1257.96 | E7: =COUNTIFS(Ausleihen!$A$2:$A$46,A7,Ausleihen!$D$2:$D$46,"") -> 1 | F7: =IF(E7>0,"im Einsatz","nicht im Einsatz") -> im Einsatz | H7: Aufbau
A8: =Geraete!A8 -> G0007 | B8: =Geraete!B8 -> Laptop | C8: =Geraete!C8 -> Lenovo ThinkPad | D8: =Geraete!E8 -> 869.09 | E8: =COUNTIFS(Ausleihen!$A$2:$A$46,A8,Ausleihen!$D$2:$D$46,"") -> 1 | F8: =IF(E8>0,"im Einsatz","nicht im Einsatz") -> im Einsatz | H8: 1. Spalte E zählt je Gerät die Ausleihen ohne Rückgabedatum (ZÄHLENWENNS auf Blatt Ausleihen, „Rückgabe am“ leer).
A9: =Geraete!A9 -> G0008 | B9: =Geraete!B9 -> Beamer | C9: =Geraete!C9 -> Epson EB | D9: =Geraete!E9 -> 1323.76 | E9: =COUNTIFS(Ausleihen!$A$2:$A$46,A9,Ausleihen!$D$2:$D$46,"") -> 0 | F9: =IF(E9>0,"im Einsatz","nicht im Einsatz") -> nicht im Einsatz | H9: 2. Spalte F: mindestens eine offene Ausleihe = „im Einsatz“, sonst „nicht im Einsatz“.
A10: =Geraete!A10 -> G0009 | B10: =Geraete!B10 -> Laptop | C10: =Geraete!C10 -> Dell XPS | D10: =Geraete!E10 -> 1458.02 | E10: =COUNTIFS(Ausleihen!$A$2:$A$46,A10,Ausleihen!$D$2:$D$46,"") -> 0 | F10: =IF(E10>0,"im Einsatz","nicht im Einsatz") -> nicht im Einsatz | H10: 3. I3 summiert den Netto-Kaufpreis aller Geräte mit Status „nicht im Einsatz“ (SUMMEWENN).
A11: =Geraete!A11 -> G0010 | B11: =Geraete!B11 -> Laptop | C11: =Geraete!C11 -> Dell XPS | D11: =Geraete!E11 -> 1786.37 | E11: =COUNTIFS(Ausleihen!$A$2:$A$46,A11,Ausleihen!$D$2:$D$46,"") -> 0 | F11: =IF(E11>0,"im Einsatz","nicht im Einsatz") -> nicht im Einsatz | H11: Annahme: leeres Rückgabedatum = Gerät ist noch ausgeliehen. Nie ausgeliehene Geräte zählen als nicht im Einsatz.
A12: =Geraete!A12 -> G0011 | B12: =Geraete!B12 -> Drucker | C12: =Geraete!C12 -> Brother HL | D12: =Geraete!E12 -> 1417.1 | E12: =COUNTIFS(Ausleihen!$A$2:$A$46,A12,Ausleihen!$D$2:$D$46,"") -> 0 | F12: =IF(E12>0,"im Einsatz","nicht im Einsatz") -> nicht im Einsatz | H12: Wert = Netto-Kaufpreis (Anschaffungswert, ohne Abschreibung).
A13: =Geraete!A13 -> G0012 | B13: =Geraete!B13 -> Tablet | C13: =Geraete!C13 -> Galaxy Tab | D13: =Geraete!E13 -> 968.43 | E13: =COUNTIFS(Ausleihen!$A$2:$A$46,A13,Ausleihen!$D$2:$D$46,"") -> 0 | F13: =IF(E13>0,"im Einsatz","nicht im Einsatz") -> nicht im Einsatz
A14: =Geraete!A14 -> G0013 | B14: =Geraete!B14 -> Drucker | C14: =Geraete!C14 -> Canon Pixma | D14: =Geraete!E14 -> 1898.65 | E14: =COUNTIFS(Ausleihen!$A$2:$A$46,A14,Ausleihen!$D$2:$D$46,"") -> 0 | F14: =IF(E14>0,"im Einsatz","nicht im Einsatz") -> nicht im Einsatz
A15: =Geraete!A15 -> G0014 | B15: =Geraete!B15 -> Laptop | C15: =Geraete!C15 -> Lenovo ThinkPad | D15: =Geraete!E15 -> 1415.97 | E15: =COUNTIFS(Ausleihen!$A$2:$A$46,A15,Ausleihen!$D$2:$D$46,"") -> 0 | F15: =IF(E15>0,"im Einsatz","nicht im Einsatz") -> nicht im Einsatz
A16: =Geraete!A16 -> G0015 | B16: =Geraete!B16 -> Smartphone | C16: =Geraete!C16 -> iPhone 13 | D16: =Geraete!E16 -> 661.44 | E16: =COUNTIFS(Ausleihen!$A$2:$A$46,A16,Ausleihen!$D$2:$D$46,"") -> 1 | F16: =IF(E16>0,"im Einsatz","nicht im Einsatz") -> im Einsatz
A17: =Geraete!A17 -> G0016 | B17: =Geraete!B17 -> Drucker | C17: =Geraete!C17 -> Canon Pixma | D17: =Geraete!E17 -> 1501.06 | E17: =COUNTIFS(Ausleihen!$A$2:$A$46,A17,Ausleihen!$D$2:$D$46,"") -> 1 | F17: =IF(E17>0,"im Einsatz","nicht im Einsatz") -> im Einsatz
A18: =Geraete!A18 -> G0017 | B18: =Geraete!B18 -> Smartphone | C18: =Geraete!C18 -> Samsung S21 | D18: =Geraete!E18 -> 1748.56 | E18: =COUNTIFS(Ausleihen!$A$2:$A$46,A18,Ausleihen!$D$2:$D$46,"") -> 0 | F18: =IF(E18>0,"im Einsatz","nicht im Einsatz") -> nicht im Einsatz
A19: =Geraete!A19 -> G0018 | B19: =Geraete!B19 -> Tablet | C19: =Geraete!C19 -> iPad | D19: =Geraete!E19 -> 1688.07 | E19: =COUNTIFS(Ausleihen!$A$2:$A$46,A19,Ausleihen!$D$2:$D$46,"") -> 0 | F19: =IF(E19>0,"im Einsatz","nicht im Einsatz") -> nicht im Einsatz
A20: =Geraete!A20 -> G0019 | B20: =Geraete!B20 -> Drucker | C20: =Geraete!C20 -> HP LaserJet | D20: =Geraete!E20 -> 737.57 | E20: =COUNTIFS(Ausleihen!$A$2:$A$46,A20,Ausleihen!$D$2:$D$46,"") -> 0 | F20: =IF(E20>0,"im Einsatz","nicht im Einsatz") -> nicht im Einsatz
A21: =Geraete!A21 -> G0020 | B21: =Geraete!B21 -> Smartphone | C21: =Geraete!C21 -> Samsung S21 | D21: =Geraete!E21 -> 740.2 | E21: =COUNTIFS(Ausleihen!$A$2:$A$46,A21,Ausleihen!$D$2:$D$46,"") -> 0 | F21: =IF(E21>0,"im Einsatz","nicht im Einsatz") -> nicht im Einsatz
A22: =Geraete!A22 -> G0021 | B22: =Geraete!B22 -> Monitor | C22: =Geraete!C22 -> Samsung Curved | D22: =Geraete!E22 -> 1134.16 | E22: =COUNTIFS(Ausleihen!$A$2:$A$46,A22,Ausleihen!$D$2:$D$46,"") -> 0 | F22: =IF(E22>0,"im Einsatz","nicht im Einsatz") -> nicht im Einsatz
A23: =Geraete!A23 -> G0022 | B23: =Geraete!B23 -> Tablet | C23: =Geraete!C23 -> iPad | D23: =Geraete!E23 -> 1591.98 | E23: =COUNTIFS(Ausleihen!$A$2:$A$46,A23,Ausleihen!$D$2:$D$46,"") -> 0 | F23: =IF(E23>0,"im Einsatz","nicht im Einsatz") -> nicht im Einsatz
A24: =Geraete!A24 -> G0023 | B24: =Geraete!B24 -> Drucker | C24: =Geraete!C24 -> Canon Pixma | D24: =Geraete!E24 -> 1335.34 | E24: =COUNTIFS(Ausleihen!$A$2:$A$46,A24,Ausleihen!$D$2:$D$46,"") -> 0 | F24: =IF(E24>0,"im Einsatz","nicht im Einsatz") -> nicht im Einsatz
... A36: =Geraete!A36 -> G0035 | B36: =Geraete!B36 -> Beamer | C36: =Geraete!C36 -> BenQ MW550 | D36: =Geraete!E36 -> 644.54 | E36: =COUNTIFS(Ausleihen!$A$2:$A$46,A36,Ausleihen!$D$2:$D$46,"") -> 4 | F36: =IF(E36>0,"im Einsatz","nicht im Einsatz") -> im Einsatz

Sheet D2_Laptop
A1: Gerätenummer | B1: Mitarbeiter-ID | C1: Ausgabe am | D1: Rückgabe am | E1: Gerätetyp | F1: Modell | G1: Kaufdatum | H1: Netto-Kaufpreis | I1: Standort Gerät | J1: Name | K1: Abteilung | L1: Standort Mitarbeiter
A2: G0009 | B2: 1011 | C2: 45850 | D2: 45853 | E2: Laptop | F2: Dell XPS | G2: 45026 | H2: 1458.02 | I2: München | J2: Auguste Davids | K2: IT | L2: Hamburg
A3: G0029 | B3: 1002 | C3: 45921 | D3: 45934 | E3: Laptop | F3: Lenovo ThinkPad | G3: 44337 | H3: 1553.15 | I3: Hamburg | J3: Eleni Hauffer | K3: IT | L3: Berlin
A4: G0031 | B4: 1004 | C4: 45320 | E4: Laptop | F4: HP EliteBook | G4: 45775 | H4: 1095.62 | I4: München | J4: Klemens Löffler | K4: Vertrieb | L4: Hamburg
A5: G0007 | B5: 1001 | C5: 45544 | D5: 45854 | E5: Laptop | F5: Lenovo ThinkPad | G5: 44360 | H5: 869.09 | I5: Hamburg | J5: Aleksandr Weinhage | K5: IT | L5: Berlin
A6: G0007 | B6: 1001 | C6: 45880 | E6: Laptop | F6: Lenovo ThinkPad | G6: 44360 | H6: 869.09 | I6: Hamburg | J6: Aleksandr Weinhage | K6: IT | L6: Berlin
A7: G0031 | B7: 1004 | C7: 45336 | E7: Laptop | F7: HP EliteBook | G7: 45775 | H7: 1095.62 | I7: München | J7: Klemens Löffler | K7: Vertrieb | L7: Hamburg
A8: G0004 | B8: 1003 | C8: 45827 | D8: 45908 | E8: Laptop | F8: Dell XPS | G8: 45782 | H8: 1007.88 | I8: München | J8: Paul Dobes-Stiffel | K8: Produktion | L8: Hamburg
A9: G0032 | B9: 1003 | C9: 45508 | D9: 45871 | E9: Laptop | F9: Lenovo ThinkPad | G9: 44876 | H9: 1801.36 | I9: München | J9: Paul Dobes-Stiffel | K9: Produktion | L9: Hamburg
A10: G0014 | B10: 1001 | C10: 45622 | D10: 45719 | E10: Laptop | F10: Lenovo ThinkPad | G10: 44258 | H10: 1415.97 | I10: Hamburg | J10: Aleksandr Weinhage | K10: IT | L10: Berlin
A11: G0004 | B11: 1001 | C11: 45880 | D11: 45881 | E11: Laptop | F11: Dell XPS | G11: 45782 | H11: 1007.88 | I11: München | J11: Aleksandr Weinhage | K11: IT | L11: Berlin

Sheet Pivot
A3: Row Labels | B3: Count of Gerätenummer | F3: Count of Gerätenummer | G3: Column Labels
A4: Beamer | B4: 12 | F4: Row Labels | G4: Berlin | H4: Hamburg | I4: München | J4: Grand Total
A5: Drucker | B5: 12 | F5: Beamer | G5: 7 | H5: 3 | I5: 2 | J5: 12
A6: Laptop | B6: 10 | F6: Drucker | G6: 9 | H6: 2 | I6: 1 | J6: 12
A7: Monitor | B7: 4 | F7: Laptop | H7: 4 | I7: 6 | J7: 10
A8: Smartphone | B8: 4 | F8: Monitor | G8: 2 | I8: 2 | J8: 4
A9: Tablet | B9: 3 | F9: Smartphone | I9: 4 | J9: 4
A10: Grand Total | B10: 45 | F10: Tablet | H10: 2 | I10: 1 | J10: 3
F11: Grand Total | G11: 18 | H11: 11 | I11: 16 | J11: 45
